Workbook
Name _015NBSA182F304SORF150LB: [1]Sheet1!$C$27
Name _100: #REF!
Name _125: #REF!
Name _150: #REF!
Name _15NBSA182F304SORF150LB: [1]Sheet1!$C$27
Name _20NBSA182F304SORF150LB: [1]Sheet1!$C$28
Name _25: #REF!
Name _25NBSA182F304SORF150LB: [1]Sheet1!$C$29
Name _32: #REF!
Name _32NBSA182F304SORF150LB: [1]Sheet1!$C$30
Name _40: #REF!
Name _50: #REF!
Name _65: #REF!
Name _80: #REF!
Name A: #N/A
Name aa: #N/A
Name aaaaaaaaa: [1]Sheet1!$C$27
Name AAAAAAAAAAA: [1]Sheet1!$C$29
Name aaaaaaaaaaaaaaaa: [3]Sheet1!$C$30
Name aaaaaaaaaaaaaaaaa: #REF!
Name aasss: [1]Sheet1!$C$28
Name asssss: [1]Sheet1!$C$29
Name AWSSSSSS: [1]Sheet1!$C$30
Name B: #N/A
Name bbb: #N/A
Name DDDDDDDDDDDDDDD: [6]Sheet1!$C$29
Name electrical: #REF!
Name FFFFSSSSSSSSSSSSSSSSSSS: [1]Sheet1!$C$29
Name hhhhhhhhhhha: [3]Sheet1!$C$27
Name kkkkkkkkkkkkkkk: [1]Sheet1!$C$30
Name MS_Bend_c_class_100: "SS Fittings IP"
Name PRINT_AREA_MI: #REF!
Name PRINT_TITLES_MI: #N/A
Name Q: #N/A
Name qqqqqqqqqqqq: #REF!
Name SSSSSSD: [1]Sheet1!$C$27
Name SSSSSSSSSSSSSS: [6]Sheet1!$C$28
Name vmst: [8]Sheet1!$C$27
Name XXXXXX: [1]Sheet1!$C$28
Name xxxxxxxxx: [6]Sheet1!$C$29
Name XXXXXXXXXXX: [6]Sheet1!$C$29
Name xxxxxxxxxxxx: [3]Sheet1!$C$29
Name XXXXXXXXXXXXXXXF: [6]Sheet1!$C$30
Name XXXXXXXXXXXXXXXXX: [1]Sheet1!$C$28
Name xxyyyyyyyyy: #REF!
Name ZZZZZZZZZXXXXXXXXXXXXXXXXXXXXXXXXXX: [1]Sheet1!$C$30

Sheet Design criteria
A1: APDDC NEW DAIRY, CAPACITY 6 LLPD expandable to 10 LLPD
B3: Design criteria considered while working out cost estimates
A5: S. N. | B5: Details of Milk Processing, Product manufacturing and Packing | C5: Quantity
A7: 1 | B7: Milk Reception & Processing | C7: 10 LLPD
B8: Three (2W + 1F) tankers reception line each of 40 KLPH | D8: 2 nos. Expandable to 3
B9: One tanker despatch line of 30 KLPH
B10: Two milk processing line each of 30 KLPH
B11: Two 30 KLPH self cleaning seperators with auto fat standardization unit
A13: 2 | B13: Reconstitution for SNF correction | D13: Powder store for 3000 sq m
A15: 3 | B15: Liquid Milk Packing | C15: 400 TLPD | D15: Cold store for 300 TL
B16: Four packing lines each with 4 (3W + 1S) high speed double head mechanical machines 10000 PPH considerd. Building to have provision for one more line | D16: 4 x 4 nos. (provision for installation of 1 more packing line in future)
A18: 4 | B18: Liquid Milk marketing /despatch
B19: In bulk (loose milk through tankers)
B20: In 500 ml & 1000 ml polypack (25% FCM, 65% Toned, 3% SM, 5% DTM, 2% standardized ) | C20: 400 TLPD
A21: 5 | B21: Curd Production | C21: 7 MTPD | D21: Curd cold store for 36 MTPD curd, lassi & butter milk
B23: Lassi & Butter Milk In 200 ml & 500 ml pouch | C23: 55 MTPD | D23: Equiv to 29 MTPD curd
A25: 8 | B25: Butter
B26: Three CBMM considered - indigenous 800 kg/hr for white butter | C26: 40 MTPD
B27: Two butter churns of 5 KL capacity for table butter | C27: 5 MTPD
A28: 10 | B28: Ghee Production | C28: 30 MTPD | D28: Ghee store 2500 sq m
B29: Ghee store considered 1000 sq m area for 30 days storage
A31: 11 | B31: Ghee Packing
B32: In 200 ml, 500 ml & 1000 ml polypack | C32: 5 MTPD
B33: In 200 ml, 500 ml, 1 L, 2 L, 5 L tins | C33: 1 MTPD
B34: In 15 L tin
A35: 12 | B35: Ice Cream Plant | C35: 5 KL/shift
B36: In 100 ml cups, candies, family pack

Sheet Sheet1
B2: Industrial building (Production Block)
C3: sqmt | D3: sqmt
A4: Reception | B4: RMRD ( 21 x 10.5 ) | C4: =21*10.5 -> 220.5 | D4: =SUM(C4:C8) -> 465.5
B5: RMRD lab ( 7 x 3.5 ) | C5: =7*3.5 -> 24.5
B6: Reception office | C6: =7*7 -> 49
B7: Stairs ( 7 x 3.5 ) | C7: =7*3.5 -> 24.5
B8: Passage ( 3.5 x 42) | C8: =3.5*42 -> 147
A10: CIP | B10: CIP (10.5 x7) | C10: =10.5*7 -> 73.5 | D10: =SUM(C10:C11) -> 98
B11: CIP store | C11: =3.5*7 -> 24.5
A13: Process | B13: Process hall ( 21 x 14) | C13: =21*14 -> 294 | D13: =SUM(C13:C14) -> 294
A16: Butter/ghee | B16: Cont. Butter making /Cr ripening | C16: =7*7 -> 49 | D16: =SUM(C16:C23) -> 441
B17: Ghee making ( 14 x 7 ) | C17: =14*7 -> 98
B18: Panel room | C18: =7*7 -> 49
B19: Butter melting/pkg mat | C19: =7*7 -> 49
B20: Reconstitution | C20: =7*7 -> 49
B21: Ghee store | C21: =7*7 -> 49
B22: SMP store | C22: =7*7 -> 49
B23: Butter cold store | C23: =7*7 -> 49
A26: Packing | B26: Pouch filling ( 14 x 14) | C26: =14*14 -> 196 | D26: =SUM(C26:C35) -> 906.5
B27: Crate washing area (14 x 10 .5 ) | C27: =14*10.5 -> 147
B28: Milk cold store ( 21 x 10.5 ) | C28: =21*10.5 -> 220.5
B29: Ind prod CS ( 7 x 10.5 ) | C29: =7*10.5 -> 73.5
B30: film store big size ( 7 x 10 .5 ) | C30: =7*10.5 -> 73.5
B31: Panel room ( 7 x 3.5 ) | C31: =7*3.5 -> 24.5
B32: Pkg mat store | C32: =7*3.5 -> 24.5
B33: passage | C33: =3.5*14 -> 49
B34: Packing section office | C34: =7*7 -> 49
B35: Lab | C35: =7*7 -> 49
B36: Indigenous Product store ( 7 x 10.5 ) | C36: =7*10.5 -> 73.5 | D36: =C36 -> 73.5
A38: First floor | B38: HMST room ( 14 x 7) | C38: =14*7 -> 98 | D38: =SUM(C38:C38) -> 98
A40: Docks | B40: All docks -( 42 x2) +(21 x2)+ 2*2*28 | C40: =(42*2)+(21*2)+(2*2*28) -> 238 | D40: =C40 -> 238
B42: Total Sqmt | D42: =SUM(D4:D40) -> 2614.5
B44: Industrial building (ServiceBlock)
A46: Boiler | B46: Boiler house including softner | C46: =14*14 -> 196 | D46: =SUM(C46:C46) -> 196
A48: Refrigeration | B48: Refrigeration room | C48: =14*7 -> 98 | D48: =C48+C49 -> 171.5
B49: Expn for refrigeration | C49: =7*10.5 -> 73.5
A51: Engg store | B51: Engg store | C51: =7*7 -> 49 | D51: =SUM(C51:C53) -> 122.5
B52: Workshop /office | C52: 49
B53: Toilet | C53: =7*3.5 -> 24.5
A55: Electricals | B55: LT room ( 14 x 7 ) | C55: =14*7 -> 98 | D55: =SUM(C55:C56) -> 196
...

Sheet civil cost est
C1: PROJECT : NAGPUR DAIRY 6 EXP 10 LLPD
C2: ENGINEERING COST ESTIMATE - CIVIL
A4: BASIC | C4: DESCRIPTION | D4: QTY | E4: UNIT | F4: UNIT RATE | G4: SUB TOTAL | H4: AMOUNT
A5: CODE | F5: Rs | G5: Rs | H5: Rs LAKHS
A7: 750-774 | C7: CIVIL WORKS
A9: 750 | B9: 00 | C9: LAND AND DEVELOPMENT
A10: 750 | B10: 01 | C10: LAND AND DEVELOPMENT | H10: =SUM(G11:G13)/100000 -> 201.2
B11: * | C11: Land development, landscaping, Soil investigation & Contour survey | D11: =(25 *4048)*0.5 -> 50600 | E11: Sqmt | F11: 200 | G11: =+F11*D11 -> 10120000
B12: * | C12: Landscaping, Garden piping , pumps, etc. | D12: 1 | E12: Lot | F12: 5000000 | G12: =+F12*D12 -> 5000000
B13: * | C13: Retaining walls etc as per site levels. | D13: 1 | E13: Lot | F13: 5000000 | G13: =+F13*D13 -> 5000000
A14: 751 | B14: 00 | C14: INDUSTRIAL BUILDING
A15: 751 | B15: 01 | C15: INDUSTRIAL BUILDING | H15: =SUM(G16:G22)/100000 -> 10218.6
B16: * | C16: Production Block (6 LLPD Expandable to 10 LLPD) + Fermented Block | D16: 13000 | E16: Sqmt | F16: 35000 | G16: =+F16*D16 -> 455000000
B17: * | C17: Service block (Refrigerantion, Boiler House, Fuel Yard, Sub-station & WTP) | D17: 3100 | E17: Sqmt | F17: 33000 | G17: =+F17*D17 -> 102300000
C18: Powder Plant Building 30 MTPD | D18: 9000 | E18: Sqmt | F18: 35000 | G18: =+F18*D18 -> 315000000
C19: Ice Cream Plant Building 25 TLPD | D19: 3500 | E19: Sqmt | F19: 35000 | G19: =+F19*D19 -> 122500000
C20: Weighbridge Cabin & Foundation (60 MT) | D20: 1 | E20: Lot | F20: =6000000*0.82 -> 4920000 | G20: =+F20*D20 -> 4920000
C21: Service & Passenger Lifts | D21: 4 | E21: Nos. | F21: =3000000*0.82 -> 2460000 | G21: =+F21*D21 -> 9840000
B22: * | C22: Misc Industrial buildings: Machine Foundations of Milk Silos, Ammonia and Air compressors, Ice Silos, Boilers and Chimney, Pipe bridge pedestals, Calendria Foundation, Shaking Bed & misc. equipment foundations. | D22: 1 | E22: LS | F22: =15000000*0.82 -> 12300000 | G22: =+F22*D22 -> 12300000
A24: 752 | B24: 00 | C24: STORAGE FACILITIES/BUILDINGS | H24: =+SUM(G25:G30)/100000 -> 732.8
C25: Powder Store | D25: 2000 | E25: Sqmt | F25: 35000 | G25: =+F25*D25 -> 70000000
C26: General Store | D26: 0 | E26: Sqmt | F26: 30000 | G26: =+F26*D26 -> 0
C27: Packing Material Store | D27: 0 | E27: Sqmt | F27: 0 | G27: =+F27*D27 -> 0
C28: Engineering Workshop & Store | D28: 0 | E28: Sqmt | F28: 0 | G28: =+F28*D28 -> 0
C29: Chemical Store | D29: 0 | E29: Sqmt | F29: 0 | G29: =+F29*D29 -> 0
C30: Miscellaneous Scrap Yard | D30: 200 | E30: Sqmt | F30: 16400 | G30: =+F30*D30 -> 3280000
A31: 753 | B31: 00 | C31: NON INDUSTRIAL BUILDINGS
A32: 753 | B32: 01 | C32: NON INDUSTRIAL BUILDINGS | H32: =SUM(G33:G38)/100000 -> 662.145
B33: * | C33: Toilet block | D33: 150 | E33: Sq M | F33: =45000*0.82 -> 36900 | G33: =+F33*D33 -> 5535000
B34: * | C34: Security complex | D34: 75 | E34: Sq M | F34: =45000*0.82 -> 36900 | G34: =+F34*D34 -> 2767500
B35: * | C35: Parking cycle/scooter stand | D35: 200 | E35: LS | F35: =25000*0.82 -> 20500 | G35: =+F35*D35 -> 4100000
B36: * | C36: Electrically operated gates & Canopy | D36: 2 | E36: LS | F36: =800000*0.82 -> 656000 | G36: =+F36*D36 -> 1312000
B37: * | C37: Administration Building | D37: 750 | E37: Sq M | F37: 35000 | G37: =+F37*D37 -> 26250000
B38: * | C38: Worker Amenities, Canteen & Rest Rooms | D38: 750 | E38: Sq M | F38: 35000 | G38: =+F38*D38 -> 26250000
A40: 754 | B40: 00 | C40: COMPOUND WALL AND OTHER BUILDINGS
A41: 754 | B41: 01 | C41: COMPOUND WALL AND OTHER BUILDINGS | H41: =+G42/100000 -> 246
B42: * | C42: Compound wall/Chain link fence | D42: 1200 | E42: RM | F42: 20500 | G42: =D42*F42 -> 24600000
A44: 764 | B44: 00 | C44: BUILDING FURNISHINGS
B45: 01 | C45: OFFICE FURNISHINGS AND EQUIPMENT | H45: =SUM(G46:G48)/100000 -> 0
B46: * | C46: Lab furniture | D46: 1 | E46: LS | F46: 0 | G46: =+F46*D46 -> 0
...

Sheet COST EST. - CIVIL
C1: PROJECT : METRO DAIRY WITH POWDER PLANT ( 11 LLPD)
C3: SUBJECT : COST ESTIMATE -CIVIL
A5: BASIC | B5: S/A | C5: DESCRIPTION | D5: AMOUNT AS
A6: CODE | D6: PER APPRAISAL
D7: IN RS. LAKH
A8: 750 | B8: 00 | C8: LAND AND DEVELOPMENT | D8: =#REF! -> #REF!
A9: 750 | B9: 01 | C9: Land Development
A11: 751 | B11: 0 | C11: INDUSTRIAL BUILDINGS | D11: =#REF!+#REF!+#REF!+#REF! -> #REF!
A13: 752 | B13: 0 | C13: STORAGE BUILDING & FOUNDATION | D13: =#REF! -> #REF!
A15: 753 | B15: 0 | C15: NON INDUSTRIAL BUILDING | D15: =#REF! -> #REF!
A17: 754 | B17: 0 | C17: COMPOUND WALL & OTHER BLDGS | D17: =#REF! -> #REF!
A19: 764 | B19: 0 | C19: BUILDING FURNISHINGS | D19: =#REF! -> #REF!
A21: 766 | B21: 0 | C21: EFFLUENT TREATMENT PLANT | D21: =#REF! -> #REF!
B22: 1 | C22: ETP Civil & Mechanical
A24: 768 | B24: 0 | C24: ROADS AND PAVEMENTS | D24: =#REF! -> #REF!
A26: 769 | B26: 0 | C26: ELECTRIFICATION | D26: =#REF! -> #REF!
B27: 1 | C27: Internal Electrification contract /fixtures
A29: 770 | B29: 0 | C29: SPECIAL TREAMENT FOR BUILDINGS | D29: =#REF! -> #REF!
A31: 771 | B31: 0 | C31: EXT WATER SUPPLY & DRAINAGE | D31: =#REF! -> #REF!
A33: 771 | B33: 0 | C33: QUARTERS | D33: =#REF! -> #REF!
A36: 772 | B36: 0 | C36: CONSULTANT'S FEE | D36: =#REF! -> #REF!
B37: 1 | C37: Architectural Consultancy Fee
B38: 2 | C38: Structural Consultancy Fee
B39: 3 | C39: Other Consultancy Charges
A41: 774 | C41: OLD BUILDING DEMOLITION | D41: =#REF! -> #REF!
C43: TOTAL FOR CIVIL WORKS | D43: =SUM(D8:D42) -> #REF!

Sheet Summary of Cost Est.
A1: "A" LEVEL SUMMARY OF COST ESTIMATE
A2: DUMMY DATA
A3: SR. NO. | B3: DESCRIPTION | D3: AMOUNT IN RS. LAKH
A5: 1 | B5: CIVIL WORKS | D5: =+'Civil Cost Est.'!I63 -> 13899.41
A6: 2 | B6: PROCESSING & PRODUCTION EQUIPMENT | D6: ='Eqpt. Cost Est.'!J268 -> 10131.628
A7: 3 | B7: SERVICE EQUIPMENT | D7: ='Eqpt. Cost Est.'!J338 -> 7361.235
A8: 4 | B8: MISCELLANEOUS EQUIPMENT | D8: ='Eqpt. Cost Est.'!J397 -> 694.18993
A9: 5 | B9: ERECTION | D9: ='Eqpt. Cost Est.'!J407 -> 1909.6405
A10: 6 | B10: Tender Advertisement cost | D10: 25
A11: 7 | B11: TSF ON SL. Nos. 1 - 6 @ 4.25% | D11: =(SUM(D5:D10))*4.25% -> 1445.8969
B12: GST ON TSF @ 18% | D12: =+D11*18% -> 260.26144
B13: TOTAL PROJECT COST (Rs. Lakhs) | D13: =SUM(D5:D12) -> 35727.261
B14: Say | D14: Rs. 358 Cr.
A16: Following assumptions have been made while preparing the Cost Estimate:
A17: 1 | B17: Liquid Milk Processing equipment and cost estimates worked out considering that the plant would be operated in three shifts/day.
A18: 2 | B18: The estimate has been prepared for capacities of Liquid Milk Processing . Milk Processing: 5 LLPD Liquid Milk Packing: 1.3 LLPD Fermented section: 25 TLPD Paneer Section: 2 MTPD Ghee Section: 2 MTPD Powder Plant: 30 MTPD Ice-cream (only space considered in civil building, shifting and installation of equipment from old dairy to be done by Project Authority) The capacity & quantity of equipment mentioned are tentative. Hence, It may change at later stage to meet the above requirement. The requirement may get modified keeping in view the budget constraint/ escalation of cost in future.
A19: 3 | B19: SMP Godown of 1500 MT storage capacity and Butter Deep Freeze for 1000 MT storage capacity has been considered.
A20: 4 | B20: Cost of 2 nos. 8 TPH Solid Fuel Boiler has been considered in the estimate.
A21: 5 | B21: Cost of bringing potable water not considered in the estimate.
A22: 6 | B22: It is assumed that the quality and availability of power (11 KV) supply at the proposed project site is good.
A23: 7 | B23: Cost of clearing encumbraces from the site is to be arranged and borne by Project Authority and not considered in the estimate.
A24: 8 | B24: Cost of bringing 33 KV Power Lines upto Dairy premises is not considered in the estimate.
A25: 9 | B25: Obtaining statutory approvals/clearances for Establishment of the dairy plant to be arranged out by Project Authority.
A26: 10 | B26: Expenditure towards all consumables (chemicals, fuel, oil etc.), Power, Operating Man power, Packaging Materials etc. required for testing, commissioning & trial runs not considered in the cost estimation.
A27: 11 | B27: Solar PV works of 300 KW is considered in the estimate.
A28: 12 | B28: The estimate is prepared based on the current prices prevailing in the market (May-2026). In case of delay in approval of the project, the cost estimate shall increase based on the market condition.
... A31: 15 | B31: WTP Configuration may change based on Raw Water Quality Parameters.

Sheet Civil Cost Est.
C1: DUMMY DATA
C2: COST ESTIMATE FOR CIVIL WORK
A3: BASIC | C3: Sl. No. | D3: DESCRIPTION | E3: QTY | F3: UNIT | G3: UNIT RATE | H3: SUB TOTAL | I3: AMOUNT (in Lakhs Rs.)
A5: 750 | B5: 01 | C5: 1 | D5: LAND AND DEVELOPMENT | I5: =SUM(H6:H6)/100000 -> 40
B6: * | D6: Land development & landscaping | E6: 10000 | F6: Sqmt | G6: 400 | H6: =+G6*E6 -> 4000000
A8: 751 | B8: 01 | C8: 2 | D8: INDUSTRIAL BUILDING | I8: =SUM(H9:H15)/100000 -> 7578.5
D9: Production Block with Tanker Bay, Milk Reception, Milk Cold Store , etc. | E9: 10600 | F9: Sqmt | G9: 39000 | H9: =+G9*E9 -> 413400000
D10: 30 MTPD Powder Plant with 45 days storage | E10: 7000 | F10: Sqmt | G10: 39000 | H10: =+G10*E10 -> 273000000
D11: Service Block- Refrigeration, Boiler, Substation, workshop etc. | E11: 300 | F11: Sqmt | G11: 39000 | H11: =+G11*E11 -> 11700000
D12: Foundation of Milk Silos, Refrigeration equipment ,air compressors, Boilers & Chimneys, DG set , Transformer Structural Pipe Bridges, etc. | E12: 200 | F12: Sqmt | G12: 35000 | H12: =+G12*E12 -> 7000000
D13: SMP Godown | E13: 1500 | F13: Sqmt | G13: 20000 | H13: =+G13*E13 -> 30000000
D14: Butter Deep Freezer | E14: 850 | F14: Sqmt | G14: 25000 | H14: =+G14*E14 -> 21250000
D15: Scrap Yard | E15: 100 | F15: Sqmt | G15: 15000 | H15: =+G15*E15 -> 1500000
A17: 753 | B17: 01 | C17: 3 | D17: NON INDUSTRIAL BUILDINGS | I17: =SUM(H18:H22)/100000 -> 308.4
B18: * | D18: Admin block | E18: 300 | F18: Sq M | G18: 32000 | H18: =+G18*E18 -> 9600000
B19: * | D19: WA & Canteen block | E19: 350 | F19: Sq M | G19: 32000 | H19: =+G19*E19 -> 11200000
B20: * | D20: General Store | E20: 200 | F20: Sq M | G20: 32000 | H20: =+G20*E20 -> 6400000
B21: * | D21: Toilet Block | E21: 20 | F21: Sq M | G21: 32000 | H21: =+G21*E21 -> 640000
B22: * | D22: Parking cycle/scooter stand | E22: 300 | F22: Sq M | G22: 10000 | H22: =+G22*E22 -> 3000000
A24: 754 | B24: 01 | C24: 4 | D24: COMPOUND WALL AND OTHER BUILDINGS | I24: =+H25/100000 -> 369
B25: * | D25: Compound wall/Chain link fence | E25: 1800 | F25: RM | G25: 20500 | H25: =E25*G25 -> 36900000
A27: 764 | B27: 00 | D27: BUILDING FURNISHINGS
B28: 01 | D28: OFFICE FURNISHINGS AND EQUIPMENT | I28: =SUM(H29:H31)/100000 -> 0
B29: * | D29: Lab furniture | E29: 1 | F29: LS | G29: 0 | H29: =+G29*E29 -> 0
B30: * | D30: Site office equipment & Furniture | E30: 1 | F30: LS | G30: 0 | H30: =+G30*E30 -> 0
B31: * | D31: Misc. Furnishing | E31: 1 | F31: LS | G31: 0 | H31: =+G31*E31 -> 0
A33: 766 | B33: 00 | D33: EFFLUENT TREATMENT PLANT
A34: 766 | B34: 01 | D34: EFFLUENT TREATMENT PLANT | I34: =(SUM(H35:H37))/100000 -> 0
B35: * | D35: Civil & Mechanical Works for new ETP of 7.25 LLPD capacity with | E35: 1 | F35: LS | G35: =170000000 -> 170000000
B36: * | D36: ZLD Civil & Mechanical Works for new ZLD (MBR + RO + MVR + ATFD) | E36: 1 | F36: LS | G36: =200000000*0.82 -> 164000000
D37: Civil & Mechanical Works for new ETP of 7.25 LLPD capacity with ZLD Civil & Mechanical Works for new ZLD (MBR + RO + MVR + ATFD) | E37: 1 | F37: LS | G37: =350000000*0.82 -> 287000000
A39: 768 | B39: 01 | C39: 5 | D39: ROAD AND PAVEMENTS | I39: =SUM(H40:H42)/100000 -> 480
B40: * | D40: Concrete roads /Park | E40: 18000 | F40: Sq mt | G40: =4500*0.82 -> 3690
D41: Concrete roads /Hard Park | E41: 12000 | F41: Sq mt | G41: 4000 | H41: =+G41*E41 -> 48000000
A43: 769 | B43: 01 | C43: 6 | D43: INTERNAL ELECTRIFICATION | I43: =SUM(H44:H45)/100000 -> 482.6745
B44: * | D44: Electrification Contract | E44: 1 | F44: LS | G44: =SUM(H6:H41)*0.05 -> 43879500 | H44: =+G44*E44 -> 43879500
B45: * | D45: Lighting Fixtures and Fans | E45: 1 | F45: LS | G45: =SUM(H6:H42)*0.005 -> 4387950 | H45: =+G45*E45 -> 4387950
A47: 771 | B47: 01 | C47: 7 | D47: WATER SUPPLY AND DRAINAGE | I47: =SUM(H48:H53)/100000 -> 632.92872
B48: * | D48: UG sump 10.0 Lakh Litres | E48: 1500 | F48: CUM | G48: =20000*0.82 -> 16400
B49: * | D49: UG sump for water | E49: 600 | F49: CUM | G49: 20000 | H49: =+G49*E49 -> 12000000
...

Sheet Eqpt. Cost Est.
A1: DUMMY DATA
C2: COST ESTIMATE FOR EQUIPMENT, MACHINERIES AND MEP WORK
A3: BASIC CODE | C3: Sl. No. | D3: DESCRIPTION | E3: CAPACITY | F3: QTY. | G3: UOM | H3: UNIT PRICE (Rs.) | I3: TOTAL PRICE (Rs.) | J3: AMOUNT (in Lakhs Rs.)
A4: 775-884 | C4: A | D4: PROCESS AND PRODUCTION EQUIPMENT
A5: 775 | B5: 01 | C5: 1 | D5: RECEPTION EQUIPMENT INCLUDING STORAGE | J5: =SUM(I6:I15)/100000 -> 158.40072
D6: Tanker Unloading Hose with SS Fittings 2 Hoses each of 6 Mtr. Length for each Reception Line Each hose Size : 76 mm dia. x 6 M each | E6: 76 mm x 6 Mtr. | F6: 24 | G6: Mtr. | H6: 5830 | I6: =+H6*F6 -> 139920
D7: Tanker Flusing Hoses with SS Fittings 2 Hoses each of 4 Mtr. Length for each Flushing Line Each hose Size : 38 mm dia. x 4 M each | E7: 38 mm x 4 Mtr. | F7: 32 | G7: Mtr. | H7: 5088 | I7: =+H7*F7 -> 162816
D8: Duplex PIP Type Inline Strainer (with Manual Changeover) | E8: 40 KLPH | F8: 2 | G8: Nos. | H8: 121900 | I8: =+H8*F8 -> 243800
D9: SS De-aeration Vessel | E9: 200 Ltr. | F9: 2 | G9: Nos. | H9: 150000 | I9: =+H9*F9 -> 300000
D10: Tanker Unloading Pump (VFD Operated) | E10: 40 KLPH | F10: 2 | G10: Set | H10: 175000 | I10: =+H10*F10 -> 350000
D11: Raw Milk Chiller (10 - 4 Deg. C) | E11: 40 KLPH | F11: 2 | G11: Nos. | H11: 311768 | I11: =+H11*F11 -> 623536
D12: Raw Milk Storage Silo with Bird Cage | E12: 100 KL | F12: 3 | G12: Nos. | H12: 4500000 | I12: =+H12*F12 -> 13500000
D13: Raw Milk Tanker Dispatch/Intersilo Transfer Pump (VFD Operated) | E13: 30 KLPH | F13: 1 | G13: No. | H13: 130000 | I13: =+H13*F13 -> 130000
D14: CIP Return Pump for Road Milk Tankers | E14: Suitable | F14: 2 | G14: Nos. | H14: 130000 | I14: =+H14*F14 -> 260000
D15: CIP Return Pump for RMSTs | E15: Suitable | F15: 1 | G15: No. | H15: 130000 | I15: =+H15*F15 -> 130000
A17: 776 | B17: 01 | C17: 2 | D17: CHILLING & PROCESSING EQUIPMENT FOR MILK AND CREAM | J17: =SUM(I18:I50)/100000 -> 1169.4958
D18: Raw Milk Transfer Pump (from RMST to Pasteurizer - VFD Operated) | E18: 20 KLPH | F18: 2 | G18: Nos. | H18: 130000 | I18: =+H18*F18 -> 260000
D19: Duplex PIP Type Inline Strainer (with Auto Changeover) for Pasteurizers | E19: 20 KLPH | F19: 2 | G19: Nos. | H19: 109604 | I19: =+H19*F19 -> 219208
D20: Milk Pasteurizer with all Accessories | E20: 20 KLPH | F20: 2 | G20: Nos. | H20: 3500000 | I20: =+H20*F20 -> 7000000
D21: Regenerative Type Cream Pre-Chiller (to Chill Cream to 10 - 12 deg. C coming from Separator) | E21: Suitable | F21: 2 | G21: Nos. | H21: 530000 | I21: =+H21*F21 -> 1060000
D22: Self Cleaning Type Tri Purpose Centrifuge with Auto Fat Standardization Unit | E22: 20 KLPH | F22: 2 | G22: Nos. | H22: 30000000 | I22: =+H22*F22 -> 60000000
D23: Hydro Flow unit for Separators (1 W + 1 S Pump) | E23: Suitable | F23: 1 | G23: Set | H23: =110000 + ((110000*0.03)*2) -> 116600 | I23: =+H23*F23 -> 116600
D24: Milk Homogenizer for Partial Homogenization | E24: 20 KLPH | F24: 1 | G24: Nos. | H24: 15000000 | I24: =+H24*F24 -> 15000000
D25: Electric Hoist with Monorail Structure for Separators | E25: 3 MT | F25: 1 | G25: Set | H25: =513000 + ((513000*0.03)*2) -> 543780 | I25: =+H25*F25 -> 543780
D26: Pasteurized Milk Silo with Bird Cage | E26: 100 KL | F26: 2 | G26: Nos. | H26: 4500000 | I26: =+H26*F26 -> 9000000
D27: Pasteurized Milk Silo with Bird Cage | E27: 60 KL | F27: 2 | G27: Nos. | H27: 3500000 | I27: =+H27*F27 -> 7000000
D28: Pasteurized Milk Silo with Bird Cage | E28: 30 KL | F28: 1 | G28: Nos. | H28: 3000000 | I28: =+H28*F28 -> 3000000
D29: Pasteurized Milk Tanker Dispatch / Inter Silo / Re-Processing Pump (VFD Operated) | E29: 30 KLPH | F29: 1 | G29: No. | H29: 130000 | I29: =+H29*F29 -> 130000
D30: Raw/Pasteurized Milk Dispatch Chiller | E30: 30 KLPH | F30: 1 | G30: No. | H30: 130000 | I30: =+H30*F30 -> 130000
D31: CIP Return Pump for PMSTs | E31: Suitable | F31: 2 | G31: Nos. | H31: =294121 + ((294121*0.03)*2) -> 311768.26 | I31: =+H31*F31 -> 623536.52
D32: Milk Transfer Pump to Curd Milk Pasteurizer (VFD Operated) | E32: 15 KLPH | F32: 1 | G32: No. | H32: 100000 | I32: =+H32*F32 -> 100000
D33: Milk Transfer Pump to Paneer/FM Section (VFD Operated) | E33: 20 KLPH | F33: 0 | G33: No. | H33: 111000 | I33: =+H33*F33 -> 0
D34: Milk Transfer Pump to HMST (VFD Operated) | E34: 30 KLPH | F34: 2 | G34: Nos. | H34: 114000 | I34: =+H34*F34 -> 228000
D35: Milk Re-Chiller for Pouch Filling Lines | E35: 30 KLPH | F35: 2 | G35: Nos. | H35: 114000 | I35: =+H35*F35 -> 228000
D36: Raw / Past. Milk Tanker Dispatch Hose With SS Fittings 1 Hose of 6 Mtr. Length for each Dispatch Line Hose Size : 76 mm dia. x 6 M each | E36: 76 mm x 6 Mtr. | F36: 6 | G36: Mtr. | H36: 11660 | I36: =+H36*F36 -> 69960
D37: Cream Buffer Tank | E37: 5 KL | F37: 2 | G37: Nos. | H37: 600000 | I37: =+H37*F37 -> 1200000
D38: Cream Transfer Pump to Cream Pasteurizer (VFD Operated) - Centrifugal | E38: 5 KLPH | F38: 1 | G38: No. | H38: =500000 + ((500000*0.03)*2) -> 530000 | I38: =+H38*F38 -> 530000
D39: CIP Return Pump for Cream Buffer Tank | E39: Suitable | F39: 1 | G39: No. | H39: 130000 | I39: =+H39*F39 -> 130000
D40: Cream Pasteurizer with all Accessories | E40: 5 KLPH | F40: 1 | G40: No. | H40: 2500000 | I40: =+H40*F40 -> 2500000
D41: Cream Storage cum Ripening Tank | E41: 10 KL | F41: 3 | G41: Nos. | H41: 2000000 | I41: =+H41*F41 -> 6000000
...
